Workbook
Name Slicer_smoker: #N/A
Name Slicer_Weight_Status: #N/A

Sheet OG Customer Names
A1: Customer ID | B1: name
A2: Id1 | B2: Hawks, Ms. Kelly
A3: Id2 | B3: Lehner, Mr. Matthew D
A4: Id3 | B4: Lu, Mr. Phil
A5: Id4 | B5: Osborne, Ms. Kelsey
A6: Id5 | B6: Kadala, Ms. Kristyn
A7: Id6 | B7: Baker, Mr. Russell B.
A8: Id7 | B8: Macpherson, Mr. Scott
A9: Id8 | B9: Hallman, Mr. Stephen
A10: Id9 | B10: Moran, Mr. Patrick R.
A11: Id10 | B11: Benner, Ms. Brooke N.
A12: Id11 | B12: Fierro Vargas, Ms. Paola Andrea
... A2336: Id2335 | B2336: German, Mr. Aaron K

Sheet OG Hospitalisation Details
A1: Customer ID | B1: year | C1: month | D1: date | E1: children | F1: charges | G1: Hospital tier | H1: City tier | I1: State ID
A2: Id2335 | B2: 1992 | C2: Jul | D2: 9 | E2: 0 | F2: 563.84 | G2: tier - 2 | H2: tier - 3 | I2: R1013
A3: Id2334 | B3: 1992 | C3: Nov | D3: 30 | E3: 0 | F3: 570.62 | G3: tier - 2 | H3: tier - 1 | I3: R1013
A4: Id2333 | B4: 1993 | C4: Jun | D4: 30 | E4: 0 | F4: 600 | G4: tier - 2 | H4: tier - 1 | I4: R1013
A5: Id2332 | B5: 1992 | C5: Sep | D5: 13 | E5: 0 | F5: 604.54 | G5: tier - 3 | H5: tier - 3 | I5: R1013
A6: Id2331 | B6: 1998 | C6: Jul | D6: 27 | E6: 0 | F6: 637.26 | G6: tier - 3 | H6: tier - 3 | I6: R1013
A7: Id2330 | B7: 2001 | C7: Nov | D7: 20 | E7: 0 | F7: 646.14 | G7: tier - 3 | H7: tier - 3 | I7: R1012
A8: Id2329 | B8: 1993 | C8: Jun | D8: 1 | E8: 0 | F8: 650 | G8: tier - 3 | H8: tier - 3 | I8: R1013
A9: Id2328 | B9: 1995 | C9: Jul | D9: 4 | E9: 0 | F9: 650 | G9: tier - 3 | H9: tier - 3 | I9: R1013
A10: Id2327 | B10: 2002 | C10: Nov | D10: 29 | E10: 0 | F10: 668 | G10: tier - 3 | H10: tier - 2 | I10: R1012
A11: Id2326 | B11: 1997 | C11: Nov | D11: 9 | E11: 0 | F11: 670 | G11: tier - 3 | H11: tier - 3 | I11: R1013
A12: Id2325 | B12: 2001 | C12: Sep | D12: 12 | E12: 0 | F12: 687.54 | G12: tier - 3 | H12: tier - 2 | I12: R1013
A13: Id2324 | B13: 1999 | C13: Dec | D13: 26 | E13: 0 | F13: 700 | G13: ? | H13: tier - 3 | I13: R1013
... A1050: Id1290 | B1050: 1977 | C1050: Jul | D1050: 26 | E1050: 2 | F1050: 8527.53 | G1050: tier - 2 | H1050: tier - 2 | I1050: R1013
A1051: Id1289 | B1051: ? | C1051: Jul | D1051: 24 | E1051: 0 | F1051: 8534.67 | G1051: tier - 2 | H1051: tier - 3 | I1051: R1024
A1052: Id1288 | B1052: 1981 | C1052: Dec | D1052: 27 | E1052: 3 | F1052: 8538.29 | G1052: tier - 2 | H1052: tier - 3 | I1052: R1024
A1053: Id1287 | B1053: 1975 | C1053: Nov | D1053: 6 | E1053: 1 | F1053: 8539.67 | G1053: tier - 2 | H1053: tier - 3 | I1053: R1011
A1054: Id1286 | B1054: ? | C1054: Dec | D1054: 12 | E1054: 1 | F1054: 8547.69 | G1054: tier - 2 | H1054: tier - 1 | I1054: R1013
A1055: Id1285 | B1055: 1975 | C1055: Aug | D1055: 6 | E1055: 1 | F1055: 8551.35 | G1055: tier - 2 | H1055: tier - 2 | I1055: R1011
A1056: Id1284 | B1056: 1975 | C1056: Aug | D1056: 21 | E1056: 1 | F1056: 8556.91 | G1056: tier - 2 | H1056: tier - 1 | I1056: R1011
A1057: Id1283 | B1057: 1988 | C1057: Sep | D1057: 21 | E1057: 3 | F1057: 8567.25 | G1057: tier - 2 | H1057: tier - 1 | I1057: R1012
A1058: Id1282 | B1058: 1975 | C1058: Sep | D1058: 26 | E1058: 1 | F1058: 8569.86 | G1058: tier - 2 | H1058: tier - 3 | I1058: R1013
A1059: Id1281 | B1059: 1982 | C1059: Dec | D1059: 6 | E1059: 3 | F1059: 8572.04 | G1059: tier - 2 | H1059: tier - 2 | I1059: R1021
A1060: Id1280 | B1060: 1987 | C1060: Nov | D1060: 11 | E1060: 3 | F1060: 8573.3 | G1060: tier - 2 | H1060: tier - 2 | I1060: R1021
A1061: Id1279 | B1061: 1983 | C1061: Dec | D1061: 30 | E1061: 5 | F1061: 8582.3 | G1061: tier - 2 | H1061: tier - 1 | I1061: R1013
A1062: Id1278 | B1062: 1983 | C1062: Jul | D1062: 25 | E1062: 5 | F1062: 8596.83 | G1062: tier - 2 | H1062: tier - 3 | I1062: R1013
A1063: Id1277 | B1063: 1973 | C1063: Jul | D1063: 11 | E1063: 0 | F1063: 8601.33 | G1063: tier - 2 | H1063: tier - 1 | I1063: R1013
A1064: Id1276 | B1064: 1977 | C1064: Sep | D1064: 24 | E1064: 2 | F1064: 8603.82 | G1064: tier - 2 | H1064: tier - 1 | I1064: R1019
A1065: Id1275 | B1065: 1977 | C1065: Nov | D1065: 12 | E1065: 2 | F1065: 8604.48 | G1065: tier - 3 | H1065: tier - 2 | I1065: R1016
A1066: Id1274 | B1066: 1977 | C1066: Oct | D1066: 15 | E1066: 3 | F1066: 8605.36 | G1066: tier - 2 | H1066: tier - 2 | I1066: R1013
... A2344: Id1 | B2344: 1968 | C2344: Oct | D2344: 12 | E2344: 0 | F2344: 63770.43 | G2344: tier - 1 | H2344: tier - 3 | I2344: R1013

Sheet OG Medical Examinations
A1: Customer ID | B1: BMI | C1: HBA1C | D1: Heart Issues | E1: Any Transplants | F1: Cancer history | G1: NumberOfMajorSurgeries | H1: smoker
A2: Id1 | B2: 47.41 | C2: 7.47 | D2: No | E2: No | F2: No | G2: No major surgery | H2: yes
A3: Id2 | B3: 30.36 | C3: 5.77 | D3: No | E3: No | F3: No | G3: No major surgery | H3: yes
A4: Id3 | B4: 34.485 | C4: 11.87 | D4: yes | E4: No | F4: No | G4: 2 | H4: yes
A5: Id4 | B5: 38.095 | C5: 6.05 | D5: No | E5: No | F5: No | G5: No major surgery | H5: yes
A6: Id5 | B6: 35.53 | C6: 5.45 | D6: No | E6: No | F6: No | G6: No major surgery | H6: yes
A7: Id6 | B7: 32.8 | C7: 6.59 | D7: No | E7: No | F7: No | G7: No major surgery | H7: yes
A8: Id7 | B8: 36.4 | C8: 6.07 | D8: No | E8: No | F8: No | G8: No major surgery | H8: yes
A9: Id8 | B9: 36.96 | C9: 7.93 | D9: No | E9: No | F9: No | G9: 3 | H9: yes
A10: Id9 | B10: 41.14 | C10: 9.58 | D10: yes | E10: No | F10: Yes | G10: 1 | H10: yes
A11: Id10 | B11: 38.06 | C11: 10.79 | D11: No | E11: No | F11: No | G11: No major surgery | H11: yes
A12: Id11 | B12: 37.7 | C12: 5.96 | D12: yes | E12: No | F12: No | G12: 2 | H12: yes
A13: Id12 | B13: 42.13 | C13: 11.9 | D13: No | E13: No | F13: No | G13: No major surgery | H13: yes
A14: Id13 | B14: 40.92 | C14: 8.41 | D14: No | E14: No | F14: No | G14: No major surgery | H14: yes
A15: Id14 | B15: 40.565 | C15: 7.02 | D15: No | E15: No | F15: No | G15: No major surgery | H15: yes
A16: Id15 | B16: 36.385 | C16: 7.59 | D16: yes | E16: No | F16: No | G16: 2 | H16: yes
A17: Id16 | B17: 39.9 | C17: 11.32 | D17: No | E17: No | F17: No | G17: No major surgery | H17: yes
A18: Id17 | B18: 33.8 | C18: 7.67 | D18: No | E18: No | F18: No | G18: 3 | H18: yes
A19: Id18 | B19: 36.765 | C19: 7.29 | D19: yes | E19: No | F19: Yes | G19: 1 | H19: yes
A20: Id19 | B20: 36.955 | C20: 4.72 | D20: yes | E20: No | F20: No | G20: 1 | H20: yes
A21: Id20 | B21: 42.9 | C21: 11.41 | D21: No | E21: No | F21: No | G21: No major surgery | H21: yes
A22: Id21 | B22: 36.3 | C22: 11.5 | D22: yes | E22: No | F22: No | G22: 2 | H22: yes
A23: Id22 | B23: 32.2 | C23: 6.22 | D23: yes | E23: No | F23: No | G23: 2 | H23: yes
A24: Id23 | B24: 31.3 | C24: 11.38 | D24: No | E24: No | F24: No | G24: 3 | H24: yes
A25: Id24 | B25: 41.8 | C25: 7.89 | D25: yes | E25: No | F25: No | G25: 2 | H25: yes
A26: Id25 | B26: 35.09 | C26: 4.38 | D26: yes | E26: No | F26: No | G26: 2 | H26: yes
A27: Id26 | B27: 33.88 | C27: 7.01 | D27: No | E27: No | F27: No | G27: 3 | H27: yes
A28: Id27 | B28: 30.875 | C28: 11.88 | D28: No | E28: No | F28: No | G28: No major surgery | H28: yes
A29: Id28 | B29: 36.86 | C29: 5.19 | D29: yes | E29: No | F29: Yes | G29: 1 | H29: yes
A30: Id29 | B30: 35.86 | C30: 6.74 | D30: yes | E30: No | F30: No | G30: 2 | H30: yes
A31: Id30 | B31: 37.05 | C31: 8.44 | D31: No | E31: No | F31: No | G31: No major surgery | H31: yes
A32: Id31 | B32: 43.89 | C32: 8.71 | D32: No | E32: No | F32: No | G32: No major surgery | H32: yes
A33: Id32 | B33: 42.35 | C33: 5.08 | D33: yes | E33: No | F33: No | G33: No major surgery | H33: yes
A34: Id33 | B34: 31.35 | C34: 6.86 | D34: No | E34: No | F34: No | G34: No major surgery | H34: yes
A35: Id34 | B35: 47.6 | C35: 5.95 | D35: yes | E35: No | F35: No | G35: No major surgery | H35: yes
A36: Id35 | B36: 46.2 | C36: 6.09 | D36: No | E36: No | F36: Yes | G36: 1 | H36: yes
A37: Id36 | B37: 32.015 | C37: 11.75 | D37: No | E37: No | F37: No | G37: No major surgery | H37: yes
A38: Id37 | B38: 40.565 | C38: 7.37 | D38: No | E38: No | F38: No | G38: No major surgery | H38: yes
A39: Id38 | B39: 32.45 | C39: 11.91 | D39: No | E39: No | F39: No | G39: No major surgery | H39: yes
A40: Id39 | B40: 34.96 | C40: 6.52 | D40: No | E40: No | F40: No | G40: No major surgery | H40: yes
...

Sheet Dashboard
A1: Healthcare Dashboard – AI Analysis | M1: Healthcare Statistics
M2: Total customers count | N2: =COUNTA(Table1[[#Data],[#Totals],[Customer ID]]) -> 2336
M3: Total Healthcare Costs | N3: =SUM(Table1[charges]) -> 31592359
M4: Average Charges | N4: =AVERAGE(Table1[[#Data],[#Totals],[charges]]) -> 13529.918
M5: Average BMI | N5: =AVERAGE(Table1[BMI]) -> 30.972649
M6: Average HBA1C | N6: =AVERAGE(Table1[HBA1C]) -> 6.5789979
M7: Average Age | N7: =AVERAGE(Table1[Age]) -> 39.228694
M8: Total hospitalisation count | N8: =COUNTA(Table1[[#Data],[#Totals],[Customer ID]]) -> 2336

Sheet Cancer History
A3: Count of Customer ID | B3: Column Labels
A4: Row Labels | B4: No | C4: Yes | D4: Grand Total
A5: No | B5: 1539 | C5: 307 | D5: 1846
A6: Yes | B6: 405 | C6: 84 | D6: 489
A7: Grand Total | B7: 1944 | C7: 391 | D7: 2335

Sheet Weight Status
A3: Row Labels | B3: Sum of charges
A4: Normal Weight | B4: 4305290.1
A5: Obesity | B5: 20343647
A6: Overweight | B6: 5729141.8
A7: Underweight | B7: 1214279.9
A8: Grand Total | B8: 31592359

Sheet Healthcare
A1: Customer ID | B1: First Name | C1: BMI | D1: HBA1C | E1: Heart Issues | F1: Any Transplants | G1: Cancer history | H1: NumberOfMajorSurgeries | I1: smoker | J1: Weight Status | K1: Date of Birth | L1: charges | M1: Hospital tier | N1: City tier | O1: State ID | P1: Age | R1: Healthcare Statistics
A2: Id1 | B2: =_xlfn.XLOOKUP(A2,'Customer Names'!A:A,'Customer Names'!C:C,"Not Found") -> Hawks | C2: =_xlfn.XLOOKUP($A$2,'Medical Examinations'!$A:$A,'Medical Examinations'!B:B,"not found") -> 47.41 | D2: =_xlfn.XLOOKUP(A2,'Medical Examinations'!A:A,'Medical Examinations'!C:C,"not found") -> 7.47 | E2: =_xlfn.XLOOKUP(A2,'Medical Examinations'!A:A,'Medical Examinations'!D:D,"not found") -> No | F2: =_xlfn.XLOOKUP(A2,'Medical Examinations'!A:A,'Medical Examinations'!E:E,"not found") -> No | G2: =_xlfn.XLOOKUP(A2,'Medical Examinations'!A:A,'Medical Examinations'!F:F,"not found") -> No | H2: =_xlfn.XLOOKUP(A2,'Medical Examinations'!A:A,'Medical Examinations'!G:G,"not found") -> 0 | I2: =_xlfn.XLOOKUP(A2,'Medical Examinations'!A:A,'Medical Examinations'!H:H,"not found") -> Yes | J2: =_xlfn.XLOOKUP(A2,'Medical Examinations'!A:A,'Medical Examinations'!I:I,"not found") -> Obesity | K2: =_xlfn.XLOOKUP($A$2,'Hospitalisation Details'!$A:$A,'Hospitalisation Details'!F:F,"Not Found") -> 25123 | L2: =_xlfn.XLOOKUP(A2,'Hospitalisation Details'!A:A,'Hospitalisation Details'!H:H,"Not Found") -> 63770.43 | M2: =_xlfn.XLOOKUP(A2,'Hospitalisation Details'!A:A,'Hospitalisation Details'!I:I,"Not Found") -> tier - 1 | N2: =_xlfn.XLOOKUP(A2,'Hospitalisation Details'!A:A,'Hospitalisation Details'!J:J,"Not Found") -> tier - 3 | O2: =_xlfn.XLOOKUP(A2,'Hospitalisation Details'!A:A,'Hospitalisation Details'!K:K,"Not Found") -> R1013 | P2: =_xlfn.XLOOKUP(A2,'Hospitalisation Details'!A:A,'Hospitalisation Details'!L:L,"Not Found") -> 54 | R2: Total customers count | S2: =COUNTA(Table1[[#Data],[#Totals],[Customer ID]]) -> 2336
A3: Id2 | B3: =_xlfn.XLOOKUP(A3,'Customer Names'!A:A,'Customer Names'!C:C,"Not Found") -> Lehner | C3: =_xlfn.XLOOKUP(A3,'Medical Examinations'!A:A,'Medical Examinations'!B:B,"not found") -> 30.36 | D3: =_xlfn.XLOOKUP(A3,'Medical Examinations'!A:A,'Medical Examinations'!C:C,"not found") -> 5.77 | E3: =_xlfn.XLOOKUP(A3,'Medical Examinations'!A:A,'Medical Examinations'!D:D,"not found") -> No | F3: =_xlfn.XLOOKUP(A3,'Medical Examinations'!A:A,'Medical Examinations'!E:E,"not found") -> No | G3: =_xlfn.XLOOKUP(A3,'Medical Examinations'!A:A,'Medical Examinations'!F:F,"not found") -> No | H3: =_xlfn.XLOOKUP(A3,'Medical Examinations'!A:A,'Medical Examinations'!G:G,"not found") -> 0 | I3: =_xlfn.XLOOKUP(A3,'Medical Examinations'!A:A,'Medical Examinations'!H:H,"not found") -> Yes | J3: =_xlfn.XLOOKUP(A3,'Medical Examinations'!A:A,'Medical Examinations'!I:I,"not found") -> Obesity | K3: =_xlfn.XLOOKUP(A3,'Hospitalisation Details'!A:A,'Hospitalisation Details'!F:F,"Not Found") -> 28284 | L3: =_xlfn.XLOOKUP(A3,'Hospitalisation Details'!A:A,'Hospitalisation Details'!H:H,"Not Found") -> 62592.87 | M3: =_xlfn.XLOOKUP(A3,'Hospitalisation Details'!A:A,'Hospitalisation Details'!I:I,"Not Found") -> tier - 1 | N3: =_xlfn.XLOOKUP(A3,'Hospitalisation Details'!A:A,'Hospitalisation Details'!J:J,"Not Found") -> tier - 3 | O3: =_xlfn.XLOOKUP(A3,'Hospitalisation Details'!A:A,'Hospitalisation Details'!K:K,"Not Found") -> R1013 | P3: =_xlfn.XLOOKUP(A3,'Hospitalisation Details'!A:A,'Hospitalisation Details'!L:L,"Not Found") -> 46 | R3: Total Healthcare Costs | S3: =SUM(Table1[charges]) -> 31592359
A4: Id3 | B4: =_xlfn.XLOOKUP(A4,'Customer Names'!A:A,'Customer Names'!C:C,"Not Found") -> Lu | C4: =_xlfn.XLOOKUP(A4,'Medical Examinations'!A:A,'Medical Examinations'!B:B,"not found") -> 34.485 | D4: =_xlfn.XLOOKUP(A4,'Medical Examinations'!A:A,'Medical Examinations'!C:C,"not found") -> 11.87 | E4: =_xlfn.XLOOKUP(A4,'Medical Examinations'!A:A,'Medical Examinations'!D:D,"not found") -> Yes | F4: =_xlfn.XLOOKUP(A4,'Medical Examinations'!A:A,'Medical Examinations'!E:E,"not found") -> No | G4: =_xlfn.XLOOKUP(A4,'Medical Examinations'!A:A,'Medical Examinations'!F:F,"not found") -> No | H4: =_xlfn.XLOOKUP(A4,'Medical Examinations'!A:A,'Medical Examinations'!G:G,"not found") -> 2 | I4: =_xlfn.XLOOKUP(A4,'Medical Examinations'!A:A,'Medical Examinations'!H:H,"not found") -> Yes | J4: =_xlfn.XLOOKUP(A4,'Medical Examinations'!A:A,'Medical Examinations'!I:I,"not found") -> Obesity | K4: =_xlfn.XLOOKUP(A4,'Hospitalisation Details'!A:A,'Hospitalisation Details'!F:F,"Not Found") -> 25822 | L4: =_xlfn.XLOOKUP(A4,'Hospitalisation Details'!A:A,'Hospitalisation Details'!H:H,"Not Found") -> 60021.4 | M4: =_xlfn.XLOOKUP(A4,'Hospitalisation Details'!A:A,'Hospitalisation Details'!I:I,"Not Found") -> tier - 1 | N4: =_xlfn.XLOOKUP(A4,'Hospitalisation Details'!A:A,'Hospitalisation Details'!J:J,"Not Found") -> tier - 3 | O4: =_xlfn.XLOOKUP(A4,'Hospitalisation Details'!A:A,'Hospitalisation Details'!K:K,"Not Found") -> R1012 | P4: =_xlfn.XLOOKUP(A4,'Hospitalisation Details'!A:A,'Hospitalisation Details'!L:L,"Not Found") -> 52 | R4: Average Charges | S4: =AVERAGE(Table1[[#Data],[#Totals],[charges]]) -> 13529.918
A5: Id4 | B5: =_xlfn.XLOOKUP(A5,'Customer Names'!A:A,'Customer Names'!C:C,"Not Found") -> Osborne | C5: =_xlfn.XLOOKUP(A5,'Medical Examinations'!A:A,'Medical Examinations'!B:B,"not found") -> 38.095 | D5: =_xlfn.XLOOKUP(A5,'Medical Examinations'!A:A,'Medical Examinations'!C:C,"not found") -> 6.05 | E5: =_xlfn.XLOOKUP(A5,'Medical Examinations'!A:A,'Medical Examinations'!D:D,"not found") -> No | F5: =_xlfn.XLOOKUP(A5,'Medical Examinations'!A:A,'Medical Examinations'!E:E,"not found") -> No | G5: =_xlfn.XLOOKUP(A5,'Medical Examinations'!A:A,'Medical Examinations'!F:F,"not found") -> No | H5: =_xlfn.XLOOKUP(A5,'Medical Examinations'!A:A,'Medical Examinations'!G:G,"not found") -> 0 | I5: =_xlfn.XLOOKUP(A5,'Medical Examinations'!A:A,'Medical Examinations'!H:H,"not found") -> Yes | J5: =_xlfn.XLOOKUP(A5,'Medical Examinations'!A:A,'Medical Examinations'!I:I,"not found") -> Obesity | K5: =_xlfn.XLOOKUP(A5,'Hospitalisation Details'!A:A,'Hospitalisation Details'!F:F,"Not Found") -> 33395 | L5: =_xlfn.XLOOKUP(A5,'Hospitalisation Details'!A:A,'Hospitalisation Details'!H:H,"Not Found") -> 58571.07 | M5: =_xlfn.XLOOKUP(A5,'Hospitalisation Details'!A:A,'Hospitalisation Details'!I:I,"Not Found") -> tier - 1 | N5: =_xlfn.XLOOKUP(A5,'Hospitalisation Details'!A:A,'Hospitalisation Details'!J:J,"Not Found") -> tier - 3 | O5: =_xlfn.XLOOKUP(A5,'Hospitalisation Details'!A:A,'Hospitalisation Details'!K:K,"Not Found") -> R1024 | P5: =_xlfn.XLOOKUP(A5,'Hospitalisation Details'!A:A,'Hospitalisation Details'!L:L,"Not Found") -> 32 | R5: Average BMI | S5: =AVERAGE(Table1[BMI]) -> 30.972649
A6: Id5 | B6: =_xlfn.XLOOKUP(A6,'Customer Names'!A:A,'Customer Names'!C:C,"Not Found") -> Kadala | C6: =_xlfn.XLOOKUP(A6,'Medical Examinations'!A:A,'Medical Examinations'!B:B,"not found") -> 35.53 | D6: =_xlfn.XLOOKUP(A6,'Medical Examinations'!A:A,'Medical Examinations'!C:C,"not found") -> 5.45 | E6: =_xlfn.XLOOKUP(A6,'Medical Examinations'!A:A,'Medical Examinations'!D:D,"not found") -> No | F6: =_xlfn.XLOOKUP(A6,'Medical Examinations'!A:A,'Medical Examinations'!E:E,"not found") -> No | G6: =_xlfn.XLOOKUP(A6,'Medical Examinations'!A:A,'Medical Examinations'!F:F,"not found") -> No | H6: =_xlfn.XLOOKUP(A6,'Medical Examinations'!A:A,'Medical Examinations'!G:G,"not found") -> 0 | I6: =_xlfn.XLOOKUP(A6,'Medical Examinations'!A:A,'Medical Examinations'!H:H,"not found") -> Yes | J6: =_xlfn.XLOOKUP(A6,'Medical Examinations'!A:A,'Medical Examinations'!I:I,"not found") -> Obesity | K6: =_xlfn.XLOOKUP(A6,'Hospitalisation Details'!A:A,'Hospitalisation Details'!F:F,"Not Found") -> 32678 | L6: =_xlfn.XLOOKUP(A6,'Hospitalisation Details'!A:A,'Hospitalisation Details'!H:H,"Not Found") -> 55135.4 | M6: =_xlfn.XLOOKUP(A6,'Hospitalisation Details'!A:A,'Hospitalisation Details'!I:I,"Not Found") -> tier - 1 | N6: =_xlfn.XLOOKUP(A6,'Hospitalisation Details'!A:A,'Hospitalisation Details'!J:J,"Not Found") -> tier - 3 | O6: =_xlfn.XLOOKUP(A6,'Hospitalisation Details'!A:A,'Hospitalisation Details'!K:K,"Not Found") -> R1012 | P6: =_xlfn.XLOOKUP(A6,'Hospitalisation Details'!A:A,'Hospitalisation Details'!L:L,"Not Found") -> 33 | R6: Average HBA1C | S6: =AVERAGE(Table1[HBA1C]) -> 6.5789979
A7: Id6 | B7: =_xlfn.XLOOKUP(A7,'Customer Names'!A:A,'Customer Names'!C:C,"Not Found") -> Baker | C7: =_xlfn.XLOOKUP(A7,'Medical Examinations'!A:A,'Medical Examinations'!B:B,"not found") -> 32.8 | D7: =_xlfn.XLOOKUP(A7,'Medical Examinations'!A:A,'Medical Examinations'!C:C,"not found") -> 6.59 | E7: =_xlfn.XLOOKUP(A7,'Medical Examinations'!A:A,'Medical Examinations'!D:D,"not found") -> No | F7: =_xlfn.XLOOKUP(A7,'Medical Examinations'!A:A,'Medical Examinations'!E:E,"not found") -> No | G7: =_xlfn.XLOOKUP(A7,'Medical Examinations'!A:A,'Medical Examinations'!F:F,"not found") -> No | H7: =_xlfn.XLOOKUP(A7,'Medical Examinations'!A:A,'Medical Examinations'!G:G,"not found") -> 0 | I7: =_xlfn.XLOOKUP(A7,'Medical Examinations'!A:A,'Medical Examinations'!H:H,"not found") -> Yes | J7: =_xlfn.XLOOKUP(A7,'Medical Examinations'!A:A,'Medical Examinations'!I:I,"not found") -> Obesity | K7: =_xlfn.XLOOKUP(A7,'Hospitalisation Details'!A:A,'Hospitalisation Details'!F:F,"Not Found") -> 22862 | L7: =_xlfn.XLOOKUP(A7,'Hospitalisation Details'!A:A,'Hospitalisation Details'!H:H,"Not Found") -> 52590.83 | M7: =_xlfn.XLOOKUP(A7,'Hospitalisation Details'!A:A,'Hospitalisation Details'!I:I,"Not Found") -> tier - 1 | N7: =_xlfn.XLOOKUP(A7,'Hospitalisation Details'!A:A,'Hospitalisation Details'!J:J,"Not Found") -> tier - 3 | O7: =_xlfn.XLOOKUP(A7,'Hospitalisation Details'!A:A,'Hospitalisation Details'!K:K,"Not Found") -> R1011 | P7: =_xlfn.XLOOKUP(A7,'Hospitalisation Details'!A:A,'Hospitalisation Details'!L:L,"Not Found") -> 60 | R7: Average Age | S7: =AVERAGE(Table1[Age]) -> 39.228694
A8: Id7 | B8: =_xlfn.XLOOKUP(A8,'Customer Names'!A:A,'Customer Names'!C:C,"Not Found") -> Macpherson | C8: =_xlfn.XLOOKUP(A8,'Medical Examinations'!A:A,'Medical Examinations'!B:B,"not found") -> 36.4 | D8: =_xlfn.XLOOKUP(A8,'Medical Examinations'!A:A,'Medical Examinations'!C:C,"not found") -> 6.07 | E8: =_xlfn.XLOOKUP(A8,'Medical Examinations'!A:A,'Medical Examinations'!D:D,"not found") -> No | F8: =_xlfn.XLOOKUP(A8,'Medical Examinations'!A:A,'Medical Examinations'!E:E,"not found") -> No | G8: =_xlfn.XLOOKUP(A8,'Medical Examinations'!A:A,'Medical Examinations'!F:F,"not found") -> No | H8: =_xlfn.XLOOKUP(A8,'Medical Examinations'!A:A,'Medical Examinations'!G:G,"not found") -> 0 | I8: =_xlfn.XLOOKUP(A8,'Medical Examinations'!A:A,'Medical Examinations'!H:H,"not found") -> Yes | J8: =_xlfn.XLOOKUP(A8,'Medical Examinations'!A:A,'Medical Examinations'!I:I,"not found") -> Obesity | K8: =_xlfn.XLOOKUP(A8,'Hospitalisation Details'!A:A,'Hospitalisation Details'!F:F,"Not Found") -> 34634 | L8: =_xlfn.XLOOKUP(A8,'Hospitalisation Details'!A:A,'Hospitalisation Details'!H:H,"Not Found") -> 51194.56 | M8: =_xlfn.XLOOKUP(A8,'Hospitalisation Details'!A:A,'Hospitalisation Details'!I:I,"Not Found") -> tier - 1 | N8: =_xlfn.XLOOKUP(A8,'Hospitalisation Details'!A:A,'Hospitalisation Details'!J:J,"Not Found") -> tier - 3 | O8: =_xlfn.XLOOKUP(A8,'Hospitalisation Details'!A:A,'Hospitalisation Details'!K:K,"Not Found") -> R1011 | P8: =_xlfn.XLOOKUP(A8,'Hospitalisation Details'!A:A,'Hospitalisation Details'!L:L,"Not Found") -> 28 | R8: Total hospitalisation count | S8: =COUNTA(Table1[[#Data],[#Totals],[Customer ID]]) -> 2336
A9: Id8 | B9: =_xlfn.XLOOKUP(A9,'Customer Names'!A:A,'Customer Names'!C:C,"Not Found") -> Hallman | C9: =_xlfn.XLOOKUP(A9,'Medical Examinations'!A:A,'Medical Examinations'!B:B,"not found") -> 36.96 | D9: =_xlfn.XLOOKUP(A9,'Medical Examinations'!A:A,'Medical Examinations'!C:C,"not found") -> 7.93 | E9: =_xlfn.XLOOKUP(A9,'Medical Examinations'!A:A,'Medical Examinations'!D:D,"not found") -> No | F9: =_xlfn.XLOOKUP(A9,'Medical Examinations'!A:A,'Medical Examinations'!E:E,"not found") -> No | G9: =_xlfn.XLOOKUP(A9,'Medical Examinations'!A:A,'Medical Examinations'!F:F,"not found") -> No | H9: =_xlfn.XLOOKUP(A9,'Medical Examinations'!A:A,'Medical Examinations'!G:G,"not found") -> 3 | I9: =_xlfn.XLOOKUP(A9,'Medical Examinations'!A:A,'Medical Examinations'!H:H,"not found") -> Yes | J9: =_xlfn.XLOOKUP(A9,'Medical Examinations'!A:A,'Medical Examinations'!I:I,"not found") -> Obesity | K9: =_xlfn.XLOOKUP(A9,'Hospitalisation Details'!A:A,'Hospitalisation Details'!F:F,"Not Found") -> 21363 | L9: =_xlfn.XLOOKUP(A9,'Hospitalisation Details'!A:A,'Hospitalisation Details'!H:H,"Not Found") -> 49577.66 | M9: =_xlfn.XLOOKUP(A9,'Hospitalisation Details'!A:A,'Hospitalisation Details'!I:I,"Not Found") -> tier - 1 | N9: =_xlfn.XLOOKUP(A9,'Hospitalisation Details'!A:A,'Hospitalisation Details'!J:J,"Not Found") -> tier - 3 | O9: =_xlfn.XLOOKUP(A9,'Hospitalisation Details'!A:A,'Hospitalisation Details'!K:K,"Not Found") -> R1013 | P9: =_xlfn.XLOOKUP(A9,'Hospitalisation Details'!A:A,'Hospitalisation Details'!L:L,"Not Found") -> 64
A10: Id9 | B10: =_xlfn.XLOOKUP(A10,'Customer Names'!A:A,'Customer Names'!C:C,"Not Found") -> Moran | C10: =_xlfn.XLOOKUP(A10,'Medical Examinations'!A:A,'Medical Examinations'!B:B,"not found") -> 41.14 | D10: =_xlfn.XLOOKUP(A10,'Medical Examinations'!A:A,'Medical Examinations'!C:C,"not found") -> 9.58 | E10: =_xlfn.XLOOKUP(A10,'Medical Examinations'!A:A,'Medical Examinations'!D:D,"not found") -> Yes | F10: =_xlfn.XLOOKUP(A10,'Medical Examinations'!A:A,'Medical Examinations'!E:E,"not found") -> No | G10: =_xlfn.XLOOKUP(A10,'Medical Examinations'!A:A,'Medical Examinations'!F:F,"not found") -> Yes | H10: =_xlfn.XLOOKUP(A10,'Medical Examinations'!A:A,'Medical Examinations'!G:G,"not found") -> 1 | I10: =_xlfn.XLOOKUP(A10,'Medical Examinations'!A:A,'Medical Examinations'!H:H,"not found") -> Yes | J10: =_xlfn.XLOOKUP(A10,'Medical Examinations'!A:A,'Medical Examinations'!I:I,"not found") -> Obesity | K10: =_xlfn.XLOOKUP(A10,'Hospitalisation Details'!A:A,'Hospitalisation Details'!F:F,"Not Found") -> 23258 | L10: =_xlfn.XLOOKUP(A10,'Hospitalisation Details'!A:A,'Hospitalisation Details'!H:H,"Not Found") -> 48970.25 | M10: =_xlfn.XLOOKUP(A10,'Hospitalisation Details'!A:A,'Hospitalisation Details'!I:I,"Not Found") -> tier - 1 | N10: =_xlfn.XLOOKUP(A10,'Hospitalisation Details'!A:A,'Hospitalisation Details'!J:J,"Not Found") -> tier - 3 | O10: =_xlfn.XLOOKUP(A10,'Hospitalisation Details'!A:A,'Hospitalisation Details'!K:K,"Not Found") -> R1013 | P10: =_xlfn.XLOOKUP(A10,'Hospitalisation Details'!A:A,'Hospitalisation Details'!L:L,"Not Found") -> 59
A11: Id10 | B11: =_xlfn.XLOOKUP(A11,'Customer Names'!A:A,'Customer Names'!C:C,"Not Found") -> Benner | C11: =_xlfn.XLOOKUP(A11,'Medical Examinations'!A:A,'Medical Examinations'!B:B,"not found") -> 38.06 | D11: =_xlfn.XLOOKUP(A11,'Medical Examinations'!A:A,'Medical Examinations'!C:C,"not found") -> 10.79 | E11: =_xlfn.XLOOKUP(A11,'Medical Examinations'!A:A,'Medical Examinations'!D:D,"not found") -> No | F11: =_xlfn.XLOOKUP(A11,'Medical Examinations'!A:A,'Medical Examinations'!E:E,"not found") -> No | G11: =_xlfn.XLOOKUP(A11,'Medical Examinations'!A:A,'Medical Examinations'!F:F,"not found") -> No | H11: =_xlfn.XLOOKUP(A11,'Medical Examinations'!A:A,'Medical Examinations'!G:G,"not found") -> 0 | I11: =_xlfn.XLOOKUP(A11,'Medical Examinations'!A:A,'Medical Examinations'!H:H,"not found") -> Yes | J11: =_xlfn.XLOOKUP(A11,'Medical Examinations'!A:A,'Medical Examinations'!I:I,"not found") -> Obesity | K11: =_xlfn.XLOOKUP(A11,'Hospitalisation Details'!A:A,'Hospitalisation Details'!F:F,"Not Found") -> 28853 | L11: =_xlfn.XLOOKUP(A11,'Hospitalisation Details'!A:A,'Hospitalisation Details'!H:H,"Not Found") -> 48885.14 | M11: =_xlfn.XLOOKUP(A11,'Hospitalisation Details'!A:A,'Hospitalisation Details'!I:I,"Not Found") -> tier - 1 | N11: =_xlfn.XLOOKUP(A11,'Hospitalisation Details'!A:A,'Hospitalisation Details'!J:J,"Not Found") -> tier - 3 | O11: =_xlfn.XLOOKUP(A11,'Hospitalisation Details'!A:A,'Hospitalisation Details'!K:K,"Not Found") -> R1013 | P11: =_xlfn.XLOOKUP(A11,'Hospitalisation Details'!A:A,'Hospitalisation Details'!L:L,"Not Found") -> 44
A12: Id11 | B12: =_xlfn.XLOOKUP(A12,'Customer Names'!A:A,'Customer Names'!C:C,"Not Found") -> Fierro Vargas | C12: =_xlfn.XLOOKUP(A12,'Medical Examinations'!A:A,'Medical Examinations'!B:B,"not found") -> 37.7 | D12: =_xlfn.XLOOKUP(A12,'Medical Examinations'!A:A,'Medical Examinations'!C:C,"not found") -> 5.96 | E12: =_xlfn.XLOOKUP(A12,'Medical Examinations'!A:A,'Medical Examinations'!D:D,"not found") -> Yes | F12: =_xlfn.XLOOKUP(A12,'Medical Examinations'!A:A,'Medical Examinations'!E:E,"not found") -> No | G12: =_xlfn.XLOOKUP(A12,'Medical Examinations'!A:A,'Medical Examinations'!F:F,"not found") -> No | H12: =_xlfn.XLOOKUP(A12,'Medical Examinations'!A:A,'Medical Examinations'!G:G,"not found") -> 2 | I12: =_xlfn.XLOOKUP(A12,'Medical Examinations'!A:A,'Medical Examinations'!H:H,"not found") -> Yes | J12: =_xlfn.XLOOKUP(A12,'Medical Examinations'!A:A,'Medical Examinations'!I:I,"not found") -> Obesity | K12: =_xlfn.XLOOKUP(A12,'Hospitalisation Details'!A:A,'Hospitalisation Details'!F:F,"Not Found") -> 21753 | L12: =_xlfn.XLOOKUP(A12,'Hospitalisation Details'!A:A,'Hospitalisation Details'!H:H,"Not Found") -> 48824.45 | M12: =_xlfn.XLOOKUP(A12,'Hospitalisation Details'!A:A,'Hospitalisation Details'!I:I,"Not Found") -> tier - 1 | N12: =_xlfn.XLOOKUP(A12,'Hospitalisation Details'!A:A,'Hospitalisation Details'!J:J,"Not Found") -> tier - 3 | O12: =_xlfn.XLOOKUP(A12,'Hospitalisation Details'!A:A,'Hospitalisation Details'!K:K,"Not Found") -> R1011 | P12: =_xlfn.XLOOKUP(A12,'Hospitalisation Details'!A:A,'Hospitalisation Details'!L:L,"Not Found") -> 63
A13: Id12 | B13: =_xlfn.XLOOKUP(A13,'Customer Names'!A:A,'Customer Names'!C:C,"Not Found") -> Franz | C13: =_xlfn.XLOOKUP(A13,'Medical Examinations'!A:A,'Medical Examinations'!B:B,"not found") -> 42.13 | D13: =_xlfn.XLOOKUP(A13,'Medical Examinations'!A:A,'Medical Examinations'!C:C,"not found") -> 11.9 | E13: =_xlfn.XLOOKUP(A13,'Medical Examinations'!A:A,'Medical Examinations'!D:D,"not found") -> No | F13: =_xlfn.XLOOKUP(A13,'Medical Examinations'!A:A,'Medical Examinations'!E:E,"not found") -> No | G13: =_xlfn.XLOOKUP(A13,'Medical Examinations'!A:A,'Medical Examinations'!F:F,"not found") -> No | H13: =_xlfn.XLOOKUP(A13,'Medical Examinations'!A:A,'Medical Examinations'!G:G,"not found") -> 0 | I13: =_xlfn.XLOOKUP(A13,'Medical Examinations'!A:A,'Medical Examinations'!H:H,"not found") -> Yes | J13: =_xlfn.XLOOKUP(A13,'Medical Examinations'!A:A,'Medical Examinations'!I:I,"not found") -> Obesity | K13: =_xlfn.XLOOKUP(A13,'Hospitalisation Details'!A:A,'Hospitalisation Details'!F:F,"Not Found") -> 24042 | L13: =_xlfn.XLOOKUP(A13,'Hospitalisation Details'!A:A,'Hospitalisation Details'!H:H,"Not Found") -> 48675.52 | M13: =_xlfn.XLOOKUP(A13,'Hospitalisation Details'!A:A,'Hospitalisation Details'!I:I,"Not Found") -> tier - 1 | N13: =_xlfn.XLOOKUP(A13,'Hospitalisation Details'!A:A,'Hospitalisation Details'!J:J,"Not Found") -> tier - 2 | O13: =_xlfn.XLOOKUP(A13,'Hospitalisation Details'!A:A,'Hospitalisation Details'!K:K,"Not Found") -> R1013 | P13: =_xlfn.XLOOKUP(A13,'Hospitalisation Details'!A:A,'Hospitalisation Details'!L:L,"Not Found") -> 57
A14: Id13 | B14: =_xlfn.XLOOKUP(A14,'Customer Names'!A:A,'Customer Names'!C:C,"Not Found") -> Foster | C14: =_xlfn.XLOOKUP(A14,'Medical Examinations'!A:A,'Medical Examinations'!B:B,"not found") -> 40.92 | D14: =_xlfn.XLOOKUP(A14,'Medical Examinations'!A:A,'Medical Examinations'!C:C,"not found") -> 8.41 | E14: =_xlfn.XLOOKUP(A14,'Medical Examinations'!A:A,'Medical Examinations'!D:D,"not found") -> No | F14: =_xlfn.XLOOKUP(A14,'Medical Examinations'!A:A,'Medical Examinations'!E:E,"not found") -> No | G14: =_xlfn.XLOOKUP(A14,'Medical Examinations'!A:A,'Medical Examinations'!F:F,"not found") -> No | H14: =_xlfn.XLOOKUP(A14,'Medical Examinations'!A:A,'Medical Examinations'!G:G,"not found") -> 0 | I14: =_xlfn.XLOOKUP(A14,'Medical Examinations'!A:A,'Medical Examinations'!H:H,"not found") -> Yes | J14: =_xlfn.XLOOKUP(A14,'Medical Examinations'!A:A,'Medical Examinations'!I:I,"not found") -> Obesity | K14: =_xlfn.XLOOKUP(A14,'Hospitalisation Details'!A:A,'Hospitalisation Details'!F:F,"Not Found") -> 22930 | L14: =_xlfn.XLOOKUP(A14,'Hospitalisation Details'!A:A,'Hospitalisation Details'!H:H,"Not Found") -> 48673.56 | M14: =_xlfn.XLOOKUP(A14,'Hospitalisation Details'!A:A,'Hospitalisation Details'!I:I,"Not Found") -> tier - 1 | N14: =_xlfn.XLOOKUP(A14,'Hospitalisation Details'!A:A,'Hospitalisation Details'!J:J,"Not Found") -> tier - 2 | O14: =_xlfn.XLOOKUP(A14,'Hospitalisation Details'!A:A,'Hospitalisation Details'!K:K,"Not Found") -> R1013 | P14: =_xlfn.XLOOKUP(A14,'Hospitalisation Details'!A:A,'Hospitalisation Details'!L:L,"Not Found") -> 60
A15: Id14 | B15: =_xlfn.XLOOKUP(A15,'Customer Names'!A:A,'Customer Names'!C:C,"Not Found") -> Tenorio | C15: =_xlfn.XLOOKUP(A15,'Medical Examinations'!A:A,'Medical Examinations'!B:B,"not found") -> 40.565 | D15: =_xlfn.XLOOKUP(A15,'Medical Examinations'!A:A,'Medical Examinations'!C:C,"not found") -> 7.02 | E15: =_xlfn.XLOOKUP(A15,'Medical Examinations'!A:A,'Medical Examinations'!D:D,"not found") -> No | F15: =_xlfn.XLOOKUP(A15,'Medical Examinations'!A:A,'Medical Examinations'!E:E,"not found") -> No | G15: =_xlfn.XLOOKUP(A15,'Medical Examinations'!A:A,'Medical Examinations'!F:F,"not found") -> No | H15: =_xlfn.XLOOKUP(A15,'Medical Examinations'!A:A,'Medical Examinations'!G:G,"not found") -> 0 | I15: =_xlfn.XLOOKUP(A15,'Medical Examinations'!A:A,'Medical Examinations'!H:H,"not found") -> Yes | J15: =_xlfn.XLOOKUP(A15,'Medical Examinations'!A:A,'Medical Examinations'!I:I,"not found") -> Obesity | K15: =_xlfn.XLOOKUP(A15,'Hospitalisation Details'!A:A,'Hospitalisation Details'!F:F,"Not Found") -> 25173 | L15: =_xlfn.XLOOKUP(A15,'Hospitalisation Details'!A:A,'Hospitalisation Details'!H:H,"Not Found") -> 48549.18 | M15: =_xlfn.XLOOKUP(A15,'Hospitalisation Details'!A:A,'Hospitalisation Details'!I:I,"Not Found") -> tier - 1 | N15: =_xlfn.XLOOKUP(A15,'Hospitalisation Details'!A:A,'Hospitalisation Details'!J:J,"Not Found") -> tier - 2 | O15: =_xlfn.XLOOKUP(A15,'Hospitalisation Details'!A:A,'Hospitalisation Details'!K:K,"Not Found") -> R1016 | P15: =_xlfn.XLOOKUP(A15,'Hospitalisation Details'!A:A,'Hospitalisation Details'!L:L,"Not Found") -> 54
A16: Id15 | B16: =_xlfn.XLOOKUP(A16,'Customer Names'!A:A,'Customer Names'!C:C,"Not Found") -> Rios | C16: =_xlfn.XLOOKUP(A16,'Medical Examinations'!A:A,'Medical Examinations'!B:B,"not found") -> 36.385 | D16: =_xlfn.XLOOKUP(A16,'Medical Examinations'!A:A,'Medical Examinations'!C:C,"not found") -> 7.59 | E16: =_xlfn.XLOOKUP(A16,'Medical Examinations'!A:A,'Medical Examinations'!D:D,"not found") -> Yes | F16: =_xlfn.XLOOKUP(A16,'Medical Examinations'!A:A,'Medical Examinations'!E:E,"not found") -> No | G16: =_xlfn.XLOOKUP(A16,'Medical Examinations'!A:A,'Medical Examinations'!F:F,"not found") -> No | H16: =_xlfn.XLOOKUP(A16,'Medical Examinations'!A:A,'Medical Examinations'!G:G,"not found") -> 2 | I16: =_xlfn.XLOOKUP(A16,'Medical Examinations'!A:A,'Medical Examinations'!H:H,"not found") -> Yes | J16: =_xlfn.XLOOKUP(A16,'Medical Examinations'!A:A,'Medical Examinations'!I:I,"not found") -> Obesity | K16: =_xlfn.XLOOKUP(A16,'Hospitalisation Details'!A:A,'Hospitalisation Details'!F:F,"Not Found") -> 22636 | L16: =_xlfn.XLOOKUP(A16,'Hospitalisation Details'!A:A,'Hospitalisation Details'!H:H,"Not Found") -> 48517.56 | M16: =_xlfn.XLOOKUP(A16,'Hospitalisation Details'!A:A,'Hospitalisation Details'!I:I,"Not Found") -> tier - 1 | N16: =_xlfn.XLOOKUP(A16,'Hospitalisation Details'!A:A,'Hospitalisation Details'!J:J,"Not Found") -> tier - 3 | O16: =_xlfn.XLOOKUP(A16,'Hospitalisation Details'!A:A,'Hospitalisation Details'!K:K,"Not Found") -> R1024 | P16: =_xlfn.XLOOKUP(A16,'Hospitalisation Details'!A:A,'Hospitalisation Details'!L:L,"Not Found") -> 61
A17: Id16 | B17: =_xlfn.XLOOKUP(A17,'Customer Names'!A:A,'Customer Names'!C:C,"Not Found") -> Viau-Dupuis | C17: =_xlfn.XLOOKUP(A17,'Medical Examinations'!A:A,'Medical Examinations'!B:B,"not found") -> 39.9 | D17: =_xlfn.XLOOKUP(A17,'Medical Examinations'!A:A,'Medical Examinations'!C:C,"not found") -> 11.32 | E17: =_xlfn.XLOOKUP(A17,'Medical Examinations'!A:A,'Medical Examinations'!D:D,"not found") -> No | F17: =_xlfn.XLOOKUP(A17,'Medical Examinations'!A:A,'Medical Examinations'!E:E,"not found") -> No | G17: =_xlfn.XLOOKUP(A17,'Medical Examinations'!A:A,'Medical Examinations'!F:F,"not found") -> No | H17: =_xlfn.XLOOKUP(A17,'Medical Examinations'!A:A,'Medical Examinations'!G:G,"not found") -> 0 | I17: =_xlfn.XLOOKUP(A17,'Medical Examinations'!A:A,'Medical Examinations'!H:H,"not found") -> Yes | J17: =_xlfn.XLOOKUP(A17,'Medical Examinations'!A:A,'Medical Examinations'!I:I,"not found") -> Obesity | K17: =_xlfn.XLOOKUP(A17,'Hospitalisation Details'!A:A,'Hospitalisation Details'!F:F,"Not Found") -> 22885 | L17: =_xlfn.XLOOKUP(A17,'Hospitalisation Details'!A:A,'Hospitalisation Details'!H:H,"Not Found") -> 48173.36 | M17: =_xlfn.XLOOKUP(A17,'Hospitalisation Details'!A:A,'Hospitalisation Details'!I:I,"Not Found") -> tier - 1 | N17: =_xlfn.XLOOKUP(A17,'Hospitalisation Details'!A:A,'Hospitalisation Details'!J:J,"Not Found") -> tier - 3 | O17: =_xlfn.XLOOKUP(A17,'Hospitalisation Details'!A:A,'Hospitalisation Details'!K:K,"Not Found") -> R1011 | P17: =_xlfn.XLOOKUP(A17,'Hospitalisation Details'!A:A,'Hospitalisation Details'!L:L,"Not Found") -> 60
A18: Id17 | B18: =_xlfn.XLOOKUP(A18,'Customer Names'!A:A,'Customer Names'!C:C,"Not Found") -> Cronin | C18: =_xlfn.XLOOKUP(A18,'Medical Examinations'!A:A,'Medical Examinations'!B:B,"not found") -> 33.8 | D18: =_xlfn.XLOOKUP(A18,'Medical Examinations'!A:A,'Medical Examinations'!C:C,"not found") -> 7.67 | E18: =_xlfn.XLOOKUP(A18,'Medical Examinations'!A:A,'Medical Examinations'!D:D,"not found") -> No | F18: =_xlfn.XLOOKUP(A18,'Medical Examinations'!A:A,'Medical Examinations'!E:E,"not found") -> No | G18: =_xlfn.XLOOKUP(A18,'Medical Examinations'!A:A,'Medical Examinations'!F:F,"not found") -> No | H18: =_xlfn.XLOOKUP(A18,'Medical Examinations'!A:A,'Medical Examinations'!G:G,"not found") -> 3 | I18: =_xlfn.XLOOKUP(A18,'Medical Examinations'!A:A,'Medical Examinations'!H:H,"not found") -> Yes | J18: =_xlfn.XLOOKUP(A18,'Medical Examinations'!A:A,'Medical Examinations'!I:I,"not found") -> Obesity | K18: =_xlfn.XLOOKUP(A18,'Hospitalisation Details'!A:A,'Hospitalisation Details'!F:F,"Not Found") -> 21505 | L18: =_xlfn.XLOOKUP(A18,'Hospitalisation Details'!A:A,'Hospitalisation Details'!H:H,"Not Found") -> 47928.03 | M18: =_xlfn.XLOOKUP(A18,'Hospitalisation Details'!A:A,'Hospitalisation Details'!I:I,"Not Found") -> tier - 1 | N18: =_xlfn.XLOOKUP(A18,'Hospitalisation Details'!A:A,'Hospitalisation Details'!J:J,"Not Found") -> tier - 3 | O18: =_xlfn.XLOOKUP(A18,'Hospitalisation Details'!A:A,'Hospitalisation Details'!K:K,"Not Found") -> R1011 | P18: =_xlfn.XLOOKUP(A18,'Hospitalisation Details'!A:A,'Hospitalisation Details'!L:L,"Not Found") -> 64
A19: Id18 | B19: =_xlfn.XLOOKUP(A19,'Customer Names'!A:A,'Customer Names'!C:C,"Not Found") -> Noordstar | C19: =_xlfn.XLOOKUP(A19,'Medical Examinations'!A:A,'Medical Examinations'!B:B,"not found") -> 36.765 | D19: =_xlfn.XLOOKUP(A19,'Medical Examinations'!A:A,'Medical Examinations'!C:C,"not found") -> 7.29 | E19: =_xlfn.XLOOKUP(A19,'Medical Examinations'!A:A,'Medical Examinations'!D:D,"not found") -> Yes | F19: =_xlfn.XLOOKUP(A19,'Medical Examinations'!A:A,'Medical Examinations'!E:E,"not found") -> No | G19: =_xlfn.XLOOKUP(A19,'Medical Examinations'!A:A,'Medical Examinations'!F:F,"not found") -> Yes | H19: =_xlfn.XLOOKUP(A19,'Medical Examinations'!A:A,'Medical Examinations'!G:G,"not found") -> 1 | I19: =_xlfn.XLOOKUP(A19,'Medical Examinations'!A:A,'Medical Examinations'!H:H,"not found") -> Yes | J19: =_xlfn.XLOOKUP(A19,'Medical Examinations'!A:A,'Medical Examinations'!I:I,"not found") -> Obesity | K19: =_xlfn.XLOOKUP(A19,'Hospitalisation Details'!A:A,'Hospitalisation Details'!F:F,"Not Found") -> 23228 | L19: =_xlfn.XLOOKUP(A19,'Hospitalisation Details'!A:A,'Hospitalisation Details'!H:H,"Not Found") -> 47896.79 | M19: =_xlfn.XLOOKUP(A19,'Hospitalisation Details'!A:A,'Hospitalisation Details'!I:I,"Not Found") -> tier - 1 | N19: =_xlfn.XLOOKUP(A19,'Hospitalisation Details'!A:A,'Hospitalisation Details'!J:J,"Not Found") -> tier - 3 | O19: =_xlfn.XLOOKUP(A19,'Hospitalisation Details'!A:A,'Hospitalisation Details'!K:K,"Not Found") -> R1024 | P19: =_xlfn.XLOOKUP(A19,'Hospitalisation Details'!A:A,'Hospitalisation Details'!L:L,"Not Found") -> 59
A20: Id19 | B20: =_xlfn.XLOOKUP(A20,'Customer Names'!A:A,'Customer Names'!C:C,"Not Found") -> Boudalia | C20: =_xlfn.XLOOKUP(A20,'Medical Examinations'!A:A,'Medical Examinations'!B:B,"not found") -> 36.955 | D20: =_xlfn.XLOOKUP(A20,'Medical Examinations'!A:A,'Medical Examinations'!C:C,"not found") -> 4.72 | E20: =_xlfn.XLOOKUP(A20,'Medical Examinations'!A:A,'Medical Examinations'!D:D,"not found") -> Yes | F20: =_xlfn.XLOOKUP(A20,'Medical Examinations'!A:A,'Medical Examinations'!E:E,"not found") -> No | G20: =_xlfn.XLOOKUP(A20,'Medical Examinations'!A:A,'Medical Examinations'!F:F,"not found") -> No | H20: =_xlfn.XLOOKUP(A20,'Medical Examinations'!A:A,'Medical Examinations'!G:G,"not found") -> 1 | I20: =_xlfn.XLOOKUP(A20,'Medical Examinations'!A:A,'Medical Examinations'!H:H,"not found") -> Yes | J20: =_xlfn.XLOOKUP(A20,'Medical Examinations'!A:A,'Medical Examinations'!I:I,"not found") -> Obesity | K20: =_xlfn.XLOOKUP(A20,'Hospitalisation Details'!A:A,'Hospitalisation Details'!F:F,"Not Found") -> 23688 | L20: =_xlfn.XLOOKUP(A20,'Hospitalisation Details'!A:A,'Hospitalisation Details'!H:H,"Not Found") -> 47496.49 | M20: =_xlfn.XLOOKUP(A20,'Hospitalisation Details'!A:A,'Hospitalisation Details'!I:I,"Not Found") -> tier - 1 | N20: =_xlfn.XLOOKUP(A20,'Hospitalisation Details'!A:A,'Hospitalisation Details'!J:J,"Not Found") -> tier - 3 | O20: =_xlfn.XLOOKUP(A20,'Hospitalisation Details'!A:A,'Hospitalisation Details'!K:K,"Not Found") -> R1012 | P20: =_xlfn.XLOOKUP(A20,'Hospitalisation Details'!A:A,'Hospitalisation Details'!L:L,"Not Found") -> 58
... A2336: Id2335 | B2336: =_xlfn.XLOOKUP(A2336,'Customer Names'!A:A,'Customer Names'!C:C,"Not Found") -> German | C2336: =_xlfn.XLOOKUP(A2336,'Medical Examinations'!A:A,'Medical Examinations'!B:B,"not found") -> 17.58 | D2336: =_xlfn.XLOOKUP(A2336,'Medical Examinations'!A:A,'Medical Examinations'!C:C,"not found") -> 4.51 | E2336: =_xlfn.XLOOKUP(A2336,'Medical Examinations'!A:A,'Medical Examinations'!D:D,"not found") -> No | F2336: =_xlfn.XLOOKUP(A2336,'Medical Examinations'!A:A,'Medical Examinations'!E:E,"not found") -> No | G2336: =_xlfn.XLOOKUP(A2336,'Medical Examinations'!A:A,'Medical Examinations'!F:F,"not found") -> No | H2336: =_xlfn.XLOOKUP(A2336,'Medical Examinations'!A:A,'Medical Examinations'!G:G,"not found") -> 1 | I2336: =_xlfn.XLOOKUP(A2336,'Medical Examinations'!A:A,'Medical Examinations'!H:H,"not found") -> No | J2336: =_xlfn.XLOOKUP(A2336,'Medical Examinations'!A:A,'Medical Examinations'!I:I,"not found") -> Underweight | K2336: =_xlfn.XLOOKUP(A2336,'Hospitalisation Details'!A:A,'Hospitalisation Details'!F:F,"Not Found") -> 33794 | L2336: =_xlfn.XLOOKUP(A2336,'Hospitalisation Details'!A:A,'Hospitalisation Details'!H:H,"Not Found") -> 563.84 | M2336: =_xlfn.XLOOKUP(A2336,'Hospitalisation Details'!A:A,'Hospitalisation Details'!I:I,"Not Found") -> tier - 2 | N2336: =_xlfn.XLOOKUP(A2336,'Hospitalisation Details'!A:A,'Hospitalisation Details'!J:J,"Not Found") -> tier - 2 | O2336: =_xlfn.XLOOKUP(A2336,'Hospitalisation Details'!A:A,'Hospitalisation Details'!K:K,"Not Found") -> R1013 | P2336: =_xlfn.XLOOKUP(A2336,'Hospitalisation Details'!A:A,'Hospitalisation Details'!L:L,"Not Found") -> 30
A2337: =SUBTOTAL(103,Table1[Customer ID]) -> 2335 | B2337: =SUBTOTAL(103,Table1[First Name]) -> 2335 | C2337: =SUBTOTAL(101,Table1[BMI]) -> 30.972649 | D2337: =SUBTOTAL(101,Table1[HBA1C]) -> 6.5789979 | E2337: =SUBTOTAL(103,Table1[Heart Issues]) -> 2335 | F2337: =SUBTOTAL(103,Table1[Any Transplants]) -> 2335 | G2337: =SUBTOTAL(103,Table1[Cancer history]) -> 2335 | H2337: =SUBTOTAL(103,Table1[NumberOfMajorSurgeries]) -> 2335 | I2337: =SUBTOTAL(103,Table1[smoker]) -> 2335 | J2337: =SUBTOTAL(103,Table1[Weight Status]) -> 2335 | K2337: =SUBTOTAL(103,Table1[Date of Birth]) -> 2335 | L2337: =SUBTOTAL(101,Table1[charges]) -> 13529.918 | M2337: =SUBTOTAL(103,Table1[Hospital tier]) -> 2335 | N2337: =SUBTOTAL(103,Table1[City tier]) -> 2335 | O2337: =SUBTOTAL(103,Table1[State ID]) -> 2335 | P2337: =SUBTOTAL(101,Table1[Age]) -> 39.228694

Sheet Customer Names
A1: Customer ID | B1: name | C1: First Name | D1: Title | E1: Last Name | F1: By using data/ text to column (delimited as , and . )
A2: Id1 | B2: Hawks, Ms. Kelly | C2: Hawks | D2: Ms | E2: Kelly
A3: Id2 | B3: Lehner, Mr. Matthew D | C3: Lehner | D3: Mr | E3: Matthew D
A4: Id3 | B4: Lu, Mr. Phil | C4: Lu | D4: Mr | E4: Phil
A5: Id4 | B5: Osborne, Ms. Kelsey | C5: Osborne | D5: Ms | E5: Kelsey
A6: Id5 | B6: Kadala, Ms. Kristyn | C6: Kadala | D6: Ms | E6: Kristyn
A7: Id6 | B7: Baker, Mr. Russell B. | C7: Baker | D7: Mr | E7: Russell B
A8: Id7 | B8: Macpherson, Mr. Scott | C8: Macpherson | D8: Mr | E8: Scott
A9: Id8 | B9: Hallman, Mr. Stephen | C9: Hallman | D9: Mr | E9: Stephen
A10: Id9 | B10: Moran, Mr. Patrick R. | C10: Moran | D10: Mr | E10: Patrick R
A11: Id10 | B11: Benner, Ms. Brooke N. | C11: Benner | D11: Ms | E11: Brooke N
A12: Id11 | B12: Fierro Vargas, Ms. Paola Andrea | C12: Fierro Vargas | D12: Ms | E12: Paola Andrea
A13: Id12 | B13: Franz, Mr. David | C13: Franz | D13: Mr | E13: David
... A72: Id71 | B72: Turner, Mr. Jeff | C72: Turner | D72: Mr | E72: Jeff
A73: Id72 | B73: Rangel, Mr. Elenilton V. Sr. | C73: Rangel | D73: Mr | E73: Elenilton V | F73: Sr
A74: Id73 | B74: Lacey, Ms. Maurya | C74: Lacey | D74: Ms | E74: Maurya
A75: Id74 | B75: Stiger, Ms. Samantha C | C75: Stiger | D75: Ms | E75: Samantha C
A76: Id75 | B76: Caldwell, Ms. Bethany A | C76: Caldwell | D76: Ms | E76: Bethany A
A77: Id76 | B77: Marmillod, Mr. Yves | C77: Marmillod | D77: Mr | E77: Yves
A78: Id77 | B78: Cloutier-Simons, Ms. Danielle | C78: Cloutier-Simons | D78: Ms | E78: Danielle
A79: Id78 | B79: Vegas, Ms. Julia | C79: Vegas | D79: Ms | E79: Julia
A80: Id79 | B80: Cochran, Mr. Joshua | C80: Cochran | D80: Mr | E80: Joshua
A81: Id80 | B81: Holtzapple, Ms. Jennifer | C81: Holtzapple | D81: Ms | E81: Jennifer
A82: Id81 | B82: Meyer, Ms. Gwen M. | C82: Meyer | D82: Ms | E82: Gwen M
A83: Id82 | B83: Brickley, Mr. Patrick | C83: Brickley | D83: Mr | E83: Patrick
A84: Id83 | B84: Magee, Ms. Kate | C84: Magee | D84: Ms | E84: Kate
A85: Id84 | B85: Thoma, Mr. Kevin | C85: Thoma | D85: Mr | E85: Kevin
... A188: Id187 | B188: Dublin, Mr. Andrew P | C188: Dublin | D188: Mr | E188: Andrew P
A189: Id188 | B189: Cleland, Mr. George M. V | C189: Cleland | D189: Mr | E189: George M | F189: V
A190: Id189 | B190: Evans, Ms. Sarah | C190: Evans | D190: Ms | E190: Sarah
A191: Id190 | B191: Boyd, Ms. Lara | C191: Boyd | D191: Ms | E191: Lara
A192: Id191 | B192: Roulier, Mr. Sebastien | C192: Roulier | D192: Mr | E192: Sebastien
A193: Id192 | B193: Mullins, Mr. Padraig | C193: Mullins | D193: Mr | E193: Padraig
A194: Id193 | B194: Hofmann, Ms. Heather | C194: Hofmann | D194: Ms | E194: Heather
A195: Id194 | B195: Garcia Garcia, Mr. Jorge | C195: Garcia Garcia | D195: Mr | E195: Jorge
A196: Id195 | B196: Klecker, Mr. Jack R | C196: Klecker | D196: Mr | E196: Jack R
A197: Id196 | B197: Cancre, Mr. Felix | C197: Cancre | D197: Mr | E197: Felix
A198: Id197 | B198: Denucci, Mr. Christopher C | C198: Denucci | D198: Mr | E198: Christopher C
A199: Id198 | B199: Saldana, Mr. Jesse | C199: Saldana | D199: Mr | E199: Jesse
A200: Id199 | B200: Weinberg, Ms. Jill | C200: Weinberg | D200: Ms | E200: Jill
...

Sheet Medical Examinations
A1: Customer ID | B1: BMI | C1: HBA1C | D1: Heart Issues | E1: Any Transplants | F1: Cancer history | G1: NumberOfMajorSurgeries | H1: smoker | I1: Weight Status
A2: Id1 | B2: 47.41 | C2: 7.47 | D2: No | E2: No | F2: No | G2: =IF('OG Medical Examinations'!G2="No major surgery",0,VALUE('OG Medical Examinations'!G2)) -> 0 | H2: Yes | I2: =IF(B2<18.5,"Underweight",IF(B2<25,"Normal Weight",IF(B2<30,"Overweight","Obesity"))) -> Obesity
A3: Id2 | B3: 30.36 | C3: 5.77 | D3: No | E3: No | F3: No | G3: =IF('OG Medical Examinations'!G3="No major surgery",0,VALUE('OG Medical Examinations'!G3)) -> 0 | H3: Yes | I3: =IF(B3<18.5,"Underweight",IF(B3<25,"Normal Weight",IF(B3<30,"Overweight","Obesity"))) -> Obesity
A4: Id3 | B4: 34.485 | C4: 11.87 | D4: Yes | E4: No | F4: No | G4: =IF('OG Medical Examinations'!G4="No major surgery",0,VALUE('OG Medical Examinations'!G4)) -> 2 | H4: Yes | I4: =IF(B4<18.5,"Underweight",IF(B4<25,"Normal Weight",IF(B4<30,"Overweight","Obesity"))) -> Obesity
A5: Id4 | B5: 38.095 | C5: 6.05 | D5: No | E5: No | F5: No | G5: =IF('OG Medical Examinations'!G5="No major surgery",0,VALUE('OG Medical Examinations'!G5)) -> 0 | H5: Yes | I5: =IF(B5<18.5,"Underweight",IF(B5<25,"Normal Weight",IF(B5<30,"Overweight","Obesity"))) -> Obesity
A6: Id5 | B6: 35.53 | C6: 5.45 | D6: No | E6: No | F6: No | G6: =IF('OG Medical Examinations'!G6="No major surgery",0,VALUE('OG Medical Examinations'!G6)) -> 0 | H6: Yes | I6: =IF(B6<18.5,"Underweight",IF(B6<25,"Normal Weight",IF(B6<30,"Overweight","Obesity"))) -> Obesity
A7: Id6 | B7: 32.8 | C7: 6.59 | D7: No | E7: No | F7: No | G7: =IF('OG Medical Examinations'!G7="No major surgery",0,VALUE('OG Medical Examinations'!G7)) -> 0 | H7: Yes | I7: =IF(B7<18.5,"Underweight",IF(B7<25,"Normal Weight",IF(B7<30,"Overweight","Obesity"))) -> Obesity
A8: Id7 | B8: 36.4 | C8: 6.07 | D8: No | E8: No | F8: No | G8: =IF('OG Medical Examinations'!G8="No major surgery",0,VALUE('OG Medical Examinations'!G8)) -> 0 | H8: Yes | I8: =IF(B8<18.5,"Underweight",IF(B8<25,"Normal Weight",IF(B8<30,"Overweight","Obesity"))) -> Obesity
A9: Id8 | B9: 36.96 | C9: 7.93 | D9: No | E9: No | F9: No | G9: =IF('OG Medical Examinations'!G9="No major surgery",0,VALUE('OG Medical Examinations'!G9)) -> 3 | H9: Yes | I9: =IF(B9<18.5,"Underweight",IF(B9<25,"Normal Weight",IF(B9<30,"Overweight","Obesity"))) -> Obesity
A10: Id9 | B10: 41.14 | C10: 9.58 | D10: Yes | E10: No | F10: Yes | G10: =IF('OG Medical Examinations'!G10="No major surgery",0,VALUE('OG Medical Examinations'!G10)) -> 1 | H10: Yes | I10: =IF(B10<18.5,"Underweight",IF(B10<25,"Normal Weight",IF(B10<30,"Overweight","Obesity"))) -> Obesity
A11: Id10 | B11: 38.06 | C11: 10.79 | D11: No | E11: No | F11: No | G11: =IF('OG Medical Examinations'!G11="No major surgery",0,VALUE('OG Medical Examinations'!G11)) -> 0 | H11: Yes | I11: =IF(B11<18.5,"Underweight",IF(B11<25,"Normal Weight",IF(B11<30,"Overweight","Obesity"))) -> Obesity
A12: Id11 | B12: 37.7 | C12: 5.96 | D12: Yes | E12: No | F12: No | G12: =IF('OG Medical Examinations'!G12="No major surgery",0,VALUE('OG Medical Examinations'!G12)) -> 2 | H12: Yes | I12: =IF(B12<18.5,"Underweight",IF(B12<25,"Normal Weight",IF(B12<30,"Overweight","Obesity"))) -> Obesity
A13: Id12 | B13: 42.13 | C13: 11.9 | D13: No | E13: No | F13: No | G13: =IF('OG Medical Examinations'!G13="No major surgery",0,VALUE('OG Medical Examinations'!G13)) -> 0 | H13: Yes | I13: =IF(B13<18.5,"Underweight",IF(B13<25,"Normal Weight",IF(B13<30,"Overweight","Obesity"))) -> Obesity
... A2336: Id2335 | B2336: 17.58 | C2336: 4.51 | D2336: No | E2336: No | F2336: No | G2336: =IF('OG Medical Examinations'!G2336="No major surgery",0,VALUE('OG Medical Examinations'!G2336)) -> 1 | H2336: No | I2336: =IF(B2336<18.5,"Underweight",IF(B2336<25,"Normal Weight",IF(B2336<30,"Overweight","Obesity"))) -> Underweight

Sheet Hospitalisation Details
A1: Customer ID | B1: Customer Number | C1: year | D1: month | E1: date | F1: Date of Birth | G1: children | H1: charges | I1: Hospital tier | J1: City tier | K1: State ID | L1: Age
A2: Id1 | B2: =VALUE(SUBSTITUTE(A2,"Id","")) -> 1 | C2: =IF('OG Hospitalisation Details'!B2344="?",ROUND(AVERAGE('OG Hospitalisation Details'!$B$2:$B$2344),0),'OG Hospitalisation Details'!B2344) -> 1968 | D2: =IF('OG Hospitalisation Details'!C2344="?","Sep",'OG Hospitalisation Details'!C2344) -> Oct | E2: 12 | F2: =DATE(C2,MONTH(1&D2),E2) -> 25123 | G2: 0 | H2: 63770.43 | I2: {=INDEX({"tier - 1","tier - 2","tier - 3"},MATCH(MAX(COUNTIF('OG Hospitalisation Details'!G2344:G4686,{"tier - 1","tier - 2","tier - 3"})),COUNTIF('OG Hospitalisation Details'!G2344:G4686,{"tier - 1","tier - 2","tier - 3"}),0))} -> tier - 1 | J2: {=INDEX({"tier - 1","tier - 2","tier - 3"},MATCH(MAX(COUNTIF('OG Hospitalisation Details'!H2344:H4686,{"tier - 1","tier - 2","tier - 3"})),COUNTIF('OG Hospitalisation Details'!H2344:H4686,{"tier - 1","tier - 2","tier - 3"}),0))} -> tier - 3 | K2: =IF('OG Hospitalisation Details'!I2344="?","Unknown",'OG Hospitalisation Details'!I2344) -> R1013 | L2: =DATEDIF(F2,DATE(2023,6,8),"Y") -> 54
A3: Id2 | B3: =VALUE(SUBSTITUTE(A3,"Id","")) -> 2 | C3: =IF('OG Hospitalisation Details'!B2343="?",ROUND(AVERAGE('OG Hospitalisation Details'!$B$2:$B$2344),0),'OG Hospitalisation Details'!B2343) -> 1977 | D3: =IF('OG Hospitalisation Details'!C2343="?","Sep",'OG Hospitalisation Details'!C2343) -> Jun | E3: 8 | F3: =DATE(C3,MONTH(1&D3),E3) -> 28284 | G3: 0 | H3: 62592.87 | I3: {=INDEX({"tier - 1","tier - 2","tier - 3"},MATCH(MAX(COUNTIF('OG Hospitalisation Details'!G2343:G4685,{"tier - 1","tier - 2","tier - 3"})),COUNTIF('OG Hospitalisation Details'!G2343:G4685,{"tier - 1","tier - 2","tier - 3"}),0))} -> tier - 1 | J3: {=INDEX({"tier - 1","tier - 2","tier - 3"},MATCH(MAX(COUNTIF('OG Hospitalisation Details'!H2343:H4685,{"tier - 1","tier - 2","tier - 3"})),COUNTIF('OG Hospitalisation Details'!H2343:H4685,{"tier - 1","tier - 2","tier - 3"}),0))} -> tier - 3 | K3: =IF('OG Hospitalisation Details'!I2343="?","Unknown",'OG Hospitalisation Details'!I2343) -> R1013 | L3: =DATEDIF(F3,DATE(2023,6,8),"Y") -> 46
A4: Id3 | B4: =VALUE(SUBSTITUTE(A4,"Id","")) -> 3 | C4: =IF('OG Hospitalisation Details'!B2342="?",ROUND(AVERAGE('OG Hospitalisation Details'!$B$2:$B$2344),0),'OG Hospitalisation Details'!B2342) -> 1970 | D4: =IF('OG Hospitalisation Details'!C2342="?","Sep",'OG Hospitalisation Details'!C2342) -> Sep | E4: 11 | F4: =DATE(C4,MONTH(1&D4),E4) -> 25822 | G4: 3 | H4: 60021.4 | I4: {=INDEX({"tier - 1","tier - 2","tier - 3"},MATCH(MAX(COUNTIF('OG Hospitalisation Details'!G2342:G4684,{"tier - 1","tier - 2","tier - 3"})),COUNTIF('OG Hospitalisation Details'!G2342:G4684,{"tier - 1","tier - 2","tier - 3"}),0))} -> tier - 1 | J4: {=INDEX({"tier - 1","tier - 2","tier - 3"},MATCH(MAX(COUNTIF('OG Hospitalisation Details'!H2342:H4684,{"tier - 1","tier - 2","tier - 3"})),COUNTIF('OG Hospitalisation Details'!H2342:H4684,{"tier - 1","tier - 2","tier - 3"}),0))} -> tier - 3 | K4: =IF('OG Hospitalisation Details'!I2342="?","Unknown",'OG Hospitalisation Details'!I2342) -> R1012 | L4: =DATEDIF(F4,DATE(2023,6,8),"Y") -> 52
A5: Id4 | B5: =VALUE(SUBSTITUTE(A5,"Id","")) -> 4 | C5: =IF('OG Hospitalisation Details'!B2341="?",ROUND(AVERAGE('OG Hospitalisation Details'!$B$2:$B$2344),0),'OG Hospitalisation Details'!B2341) -> 1991 | D5: =IF('OG Hospitalisation Details'!C2341="?","Sep",'OG Hospitalisation Details'!C2341) -> Jun | E5: 6 | F5: =DATE(C5,MONTH(1&D5),E5) -> 33395 | G5: 1 | H5: 58571.07 | I5: {=INDEX({"tier - 1","tier - 2","tier - 3"},MATCH(MAX(COUNTIF('OG Hospitalisation Details'!G2341:G4683,{"tier - 1","tier - 2","tier - 3"})),COUNTIF('OG Hospitalisation Details'!G2341:G4683,{"tier - 1","tier - 2","tier - 3"}),0))} -> tier - 1 | J5: {=INDEX({"tier - 1","tier - 2","tier - 3"},MATCH(MAX(COUNTIF('OG Hospitalisation Details'!H2341:H4683,{"tier - 1","tier - 2","tier - 3"})),COUNTIF('OG Hospitalisation Details'!H2341:H4683,{"tier - 1","tier - 2","tier - 3"}),0))} -> tier - 3 | K5: =IF('OG Hospitalisation Details'!I2341="?","Unknown",'OG Hospitalisation Details'!I2341) -> R1024 | L5: =DATEDIF(F5,DATE(2023,6,8),"Y") -> 32
A6: Id5 | B6: =VALUE(SUBSTITUTE(A6,"Id","")) -> 5 | C6: =IF('OG Hospitalisation Details'!B2340="?",ROUND(AVERAGE('OG Hospitalisation Details'!$B$2:$B$2344),0),'OG Hospitalisation Details'!B2340) -> 1989 | D6: =IF('OG Hospitalisation Details'!C2340="?","Sep",'OG Hospitalisation Details'!C2340) -> Jun | E6: 19 | F6: =DATE(C6,MONTH(1&D6),E6) -> 32678 | G6: 0 | H6: 55135.4 | I6: {=INDEX({"tier - 1","tier - 2","tier - 3"},MATCH(MAX(COUNTIF('OG Hospitalisation Details'!G2340:G4682,{"tier - 1","tier - 2","tier - 3"})),COUNTIF('OG Hospitalisation Details'!G2340:G4682,{"tier - 1","tier - 2","tier - 3"}),0))} -> tier - 1 | J6: {=INDEX({"tier - 1","tier - 2","tier - 3"},MATCH(MAX(COUNTIF('OG Hospitalisation Details'!H2340:H4682,{"tier - 1","tier - 2","tier - 3"})),COUNTIF('OG Hospitalisation Details'!H2340:H4682,{"tier - 1","tier - 2","tier - 3"}),0))} -> tier - 3 | K6: =IF('OG Hospitalisation Details'!I2340="?","Unknown",'OG Hospitalisation Details'!I2340) -> R1012 | L6: =DATEDIF(F6,DATE(2023,6,8),"Y") -> 33
A7: Id6 | B7: =VALUE(SUBSTITUTE(A7,"Id","")) -> 6 | C7: =IF('OG Hospitalisation Details'!B2339="?",ROUND(AVERAGE('OG Hospitalisation Details'!$B$2:$B$2344),0),'OG Hospitalisation Details'!B2339) -> 1962 | D7: =IF('OG Hospitalisation Details'!C2339="?","Sep",'OG Hospitalisation Details'!C2339) -> Aug | E7: 4 | F7: =DATE(C7,MONTH(1&D7),E7) -> 22862 | G7: 0 | H7: 52590.83 | I7: {=INDEX({"tier - 1","tier - 2","tier - 3"},MATCH(MAX(COUNTIF('OG Hospitalisation Details'!G2339:G4681,{"tier - 1","tier - 2","tier - 3"})),COUNTIF('OG Hospitalisation Details'!G2339:G4681,{"tier - 1","tier - 2","tier - 3"}),0))} -> tier - 1 | J7: {=INDEX({"tier - 1","tier - 2","tier - 3"},MATCH(MAX(COUNTIF('OG Hospitalisation Details'!H2339:H4681,{"tier - 1","tier - 2","tier - 3"})),COUNTIF('OG Hospitalisation Details'!H2339:H4681,{"tier - 1","tier - 2","tier - 3"}),0))} -> tier - 3 | K7: =IF('OG Hospitalisation Details'!I2339="?","Unknown",'OG Hospitalisation Details'!I2339) -> R1011 | L7: =DATEDIF(F7,DATE(2023,6,8),"Y") -> 60
A8: Id7 | B8: =VALUE(SUBSTITUTE(A8,"Id","")) -> 7 | C8: =IF('OG Hospitalisation Details'!B2338="?",ROUND(AVERAGE('OG Hospitalisation Details'!$B$2:$B$2344),0),'OG Hospitalisation Details'!B2338) -> 1994 | D8: =IF('OG Hospitalisation Details'!C2338="?","Sep",'OG Hospitalisation Details'!C2338) -> Oct | E8: 27 | F8: =DATE(C8,MONTH(1&D8),E8) -> 34634 | G8: 1 | H8: 51194.56 | I8: {=INDEX({"tier - 1","tier - 2","tier - 3"},MATCH(MAX(COUNTIF('OG Hospitalisation Details'!G2338:G4680,{"tier - 1","tier - 2","tier - 3"})),COUNTIF('OG Hospitalisation Details'!G2338:G4680,{"tier - 1","tier - 2","tier - 3"}),0))} -> tier - 1 | J8: {=INDEX({"tier - 1","tier - 2","tier - 3"},MATCH(MAX(COUNTIF('OG Hospitalisation Details'!H2338:H4680,{"tier - 1","tier - 2","tier - 3"})),COUNTIF('OG Hospitalisation Details'!H2338:H4680,{"tier - 1","tier - 2","tier - 3"}),0))} -> tier - 3 | K8: =IF('OG Hospitalisation Details'!I2338="?","Unknown",'OG Hospitalisation Details'!I2338) -> R1011 | L8: =DATEDIF(F8,DATE(2023,6,8),"Y") -> 28
A9: Id8 | B9: =VALUE(SUBSTITUTE(A9,"Id","")) -> 8 | C9: =IF('OG Hospitalisation Details'!B2337="?",ROUND(AVERAGE('OG Hospitalisation Details'!$B$2:$B$2344),0),'OG Hospitalisation Details'!B2337) -> 1958 | D9: =IF('OG Hospitalisation Details'!C2337="?","Sep",'OG Hospitalisation Details'!C2337) -> Jun | E9: 27 | F9: =DATE(C9,MONTH(1&D9),E9) -> 21363 | G9: 2 | H9: 49577.66 | I9: {=INDEX({"tier - 1","tier - 2","tier - 3"},MATCH(MAX(COUNTIF('OG Hospitalisation Details'!G2337:G4679,{"tier - 1","tier - 2","tier - 3"})),COUNTIF('OG Hospitalisation Details'!G2337:G4679,{"tier - 1","tier - 2","tier - 3"}),0))} -> tier - 1 | J9: {=INDEX({"tier - 1","tier - 2","tier - 3"},MATCH(MAX(COUNTIF('OG Hospitalisation Details'!H2337:H4679,{"tier - 1","tier - 2","tier - 3"})),COUNTIF('OG Hospitalisation Details'!H2337:H4679,{"tier - 1","tier - 2","tier - 3"}),0))} -> tier - 3 | K9: =IF('OG Hospitalisation Details'!I2337="?","Unknown",'OG Hospitalisation Details'!I2337) -> R1013 | L9: =DATEDIF(F9,DATE(2023,6,8),"Y") -> 64
A10: Id9 | B10: =VALUE(SUBSTITUTE(A10,"Id","")) -> 9 | C10: =IF('OG Hospitalisation Details'!B2336="?",ROUND(AVERAGE('OG Hospitalisation Details'!$B$2:$B$2344),0),'OG Hospitalisation Details'!B2336) -> 1963 | D10: =IF('OG Hospitalisation Details'!C2336="?","Sep",'OG Hospitalisation Details'!C2336) -> Sep | E10: 4 | F10: =DATE(C10,MONTH(1&D10),E10) -> 23258 | G10: 1 | H10: 48970.25 | I10: {=INDEX({"tier - 1","tier - 2","tier - 3"},MATCH(MAX(COUNTIF('OG Hospitalisation Details'!G2336:G4678,{"tier - 1","tier - 2","tier - 3"})),COUNTIF('OG Hospitalisation Details'!G2336:G4678,{"tier - 1","tier - 2","tier - 3"}),0))} -> tier - 1 | J10: {=INDEX({"tier - 1","tier - 2","tier - 3"},MATCH(MAX(COUNTIF('OG Hospitalisation Details'!H2336:H4678,{"tier - 1","tier - 2","tier - 3"})),COUNTIF('OG Hospitalisation Details'!H2336:H4678,{"tier - 1","tier - 2","tier - 3"}),0))} -> tier - 3 | K10: =IF('OG Hospitalisation Details'!I2336="?","Unknown",'OG Hospitalisation Details'!I2336) -> R1013 | L10: =DATEDIF(F10,DATE(2023,6,8),"Y") -> 59
A11: Id10 | B11: =VALUE(SUBSTITUTE(A11,"Id","")) -> 10 | C11: =IF('OG Hospitalisation Details'!B2335="?",ROUND(AVERAGE('OG Hospitalisation Details'!$B$2:$B$2344),0),'OG Hospitalisation Details'!B2335) -> 1978 | D11: =IF('OG Hospitalisation Details'!C2335="?","Sep",'OG Hospitalisation Details'!C2335) -> Dec | E11: 29 | F11: =DATE(C11,MONTH(1&D11),E11) -> 28853 | G11: 0 | H11: 48885.14 | I11: {=INDEX({"tier - 1","tier - 2","tier - 3"},MATCH(MAX(COUNTIF('OG Hospitalisation Details'!G2335:G4677,{"tier - 1","tier - 2","tier - 3"})),COUNTIF('OG Hospitalisation Details'!G2335:G4677,{"tier - 1","tier - 2","tier - 3"}),0))} -> tier - 1 | J11: {=INDEX({"tier - 1","tier - 2","tier - 3"},MATCH(MAX(COUNTIF('OG Hospitalisation Details'!H2335:H4677,{"tier - 1","tier - 2","tier - 3"})),COUNTIF('OG Hospitalisation Details'!H2335:H4677,{"tier - 1","tier - 2","tier - 3"}),0))} -> tier - 3 | K11: =IF('OG Hospitalisation Details'!I2335="?","Unknown",'OG Hospitalisation Details'!I2335) -> R1013 | L11: =DATEDIF(F11,DATE(2023,6,8),"Y") -> 44
